Workbook

Sheet ReadMe
A1: Gujarat PARAKH + PGI 2.0 / PGI-D - Comprehensive State & District Template
A3: Sheet | B3: Purpose
A4: Glossary | B4: How to fill every sheet — start here.
A5: Districts_Setup | B5: All 33 Gujarat districts, pre-filled. Edit once, everything updates.
A6: State_PGI_2.0 | B6: Gujarat state-level PGI 2.0, 101 indicators across 6 domains (out of 1000).
A7: District_PGI-D_600 | B7: District-wise PGI-D 2.0, 70 indicators across 6 categories (out of 600), all 33 districts.
A8: PARAKH_Foundational_G3 | B8: PARAKH Grade 3 competency mastery, all 33 districts.
A9: PARAKH_Preparatory_G6 | B9: PARAKH Grade 6 competency mastery, all 33 districts.
A10: PARAKH_Middle_G9 | B10: PARAKH Grade 9 competency mastery, all 33 districts.
A11: PARAKH_Subject_Performance | B11: Auto-computed average mastery per Grade-Subject, all districts.
A12: PARAKH_By_Gender | B12: Average performance split by Boys/Girls, all districts.
A13: PARAKH_By_Location | B13: Average performance split by Rural/Urban, all districts.
A14: PARAKH_By_Management | B14: Average performance split by school management type, all districts.
... A23: Combined_Performance_Ranking | B23: Merges PARAKH + PGI-D into one Composite Score, flags High/Low performing districts.
A25: Colour Key
A26: Blue text | B26: Editable input cell — type your data here
A27: Black text | B27: Formula — calculates automatically, do not overtype
A28: Light blue fill | B28: Domain subtotal
A29: Orange fill | B29: Category subtotal
A30: Yellow fill | B30: Grand total / overall score

Sheet Glossary
A1: Glossary - How to Fill Every Sheet in this Workbook
A3: 1. Core Frameworks & Sources
A4: PARAKH | B4: Performance Assessment, Review and Analysis of Knowledge for Holistic Development — NCERT's national assessment body; runs the PARAKH Rashtriya Sarvekshan (RS), testing Grades 3, 6 & 9.
A5: Stages | B5: Foundational = Grade 3, Preparatory = Grade 6, Middle = Grade 9 (NEP 2020 / NCF stage terminology used by PARAKH).
A6: PGI 2.0 (State) | B6: Performance Grading Index 2.0 — grades Gujarat out of 1000 points across 6 domains.
A7: PGI-D 2.0 (District) | B7: District-level equivalent — grades each district out of 600 points across 6 categories.
A8: UDISE+ / PRABANDH / PM-POSHAN | B8: Government data systems feeding most PGI/PGI-D indicators (infrastructure, enrolment, funds, nutrition).
A9: PARAKH Dashboard | B9: dashboard.parakh.ncert.gov.in — source for all PARAKH competency, breakdown and contextual-variable figures used in this workbook.
A11: 2. Districts_Setup
A12: Purpose | B12: Holds the master list of all 33 Gujarat districts. Pre-filled — only edit if your data source uses different boundaries (e.g. if Vav-Tharad is split out as a 34th district in your report).
A14: 3. State_PGI_2.0 (1000 points)
A15: What to enter | B15: In the blue cells (columns F, G, H), enter Gujarat's SCORE for each indicator — already on the 0-to-Weight point scale shown in column E, as per the official PGI scorecard.
A16: Domain totals/Grade | B16: Calculate automatically below the data — do not type into bold/coloured rows.
A17: Equity domain caution | B17: Domain 4 indicators measure GAPS between groups. A smaller gap earns a HIGHER score — read the note in column K for each row.
A19: 4. District_PGI-D_600 (600 points x 33 districts)
A20: What to enter | B20: Same logic as State_PGI_2.0, but one column per district (G through AM). Enter each district's awarded score (0 to the indicator's Weight).
A21: Category/Domain/Grand totals | B21: Calculate automatically in the summary block below the data, and again at the very bottom (Overall Score, % Achieved, Grade) — per district.
A23: 5. PARAKH_Foundational_G3 / Preparatory_G6 / Middle_G9
A24: What to enter | B24: For each competency (row) and district (column), enter the PROPORTION of tested students who mastered it, as a decimal 0–1 (e.g. 0.62 for 62%) — from the PARAKH RS district report or dashboard.
A25: National column | B25: Pre-filled with the National benchmark value from the PARAKH RS 2024 report; District Avg and subject-wise summaries calculate automatically.
A26: Stage grouping | B26: Foundational=Grade 3, Preparatory=Grade 6, Middle=Grade 9 — matches the PARAKH dashboard's own stage tabs.
A28: 6. PARAKH_Subject_Performance
A29: What to enter | B29: NOTHING — this sheet is 100% auto-calculated from the 3 stage sheets above. It shows each district's average mastery per Grade-Subject combination.
A31: 7. PARAKH_By_Gender / By_Location / By_Management / By_SocialGroup
A32: What to enter | B32: For each district (row) and each Grade-Subject (column group), enter the average % score for EACH category shown (e.g. Boys % and Girls % side by side), as a decimal 0–1.
A33: Where to find this | B33: PARAKH dashboard → select the relevant filter (Gender / Location / Management / Social Category) for Gujarat → read off each district's average score per grade-subject.
A34: Management categories | B34: State Govt, Govt Aided, Central Govt, Private Recognised — matches PARAKH's school-management classification.
A35: Social Group categories | B35: SC, ST, OBC, General/Others — matches PARAKH's social-category classification.
A37: 8. PARAKH_Contextual_School / Contextual_Teacher / Contextual_Pupil_G3/G6/G9
A38: What to enter | B38: One row per Broader Domain. For EACH district, there are two columns: High-Performing (%) and Low-Performing (%) — enter the proportion (0–1) of that district's High-Performing and Low-Performing schools reporting an issue/practice in this domain.
A39: Gujarat Avg columns | B39: Auto-calculated — average High-Performing % and average Low-Performing % across all 33 districts, for each domain.
A40: National column | B40: Optional — enter the National-level benchmark figure for that domain if available from the dashboard.
A41: Red highlight | B41: A district's Low-Performing value is highlighted red if it exceeds its own High-Performing value for that domain — flags domains where the high/low gap is in the expected (or unexpected) direction.
A42: Where to find this | B42: PARAKH dashboard → Contextual Variables tab (dashboard.parakh.ncert.gov.in). Aggregate the dashboard's individual variables into one score per Broader Domain, for both High- and Low-performing schools, per district.
A43: Broader Domains | B43: School: leadership & policy, training & PD, teaching & assessment, learning resources, parental/community engagement, school monitoring, student development & support, infrastructure/facilities, school environment. Teacher: professional info & experience, PD & collaboration, pedagogy & assessment, school environment & resources, social-emotional competence, job satisfaction, community support. Pupil: family background, digital device access, learning preferences, home learning environment, school environment, school accessibility/facilities, teaching-learning methods, mental health & well-being, CWSN accessibility.
A45: 9. Dashboard_PARAKH and Dashboard_PGI
A46: What to enter | B46: NOTHING — both dashboards are 100% auto-calculated and update live from the data-entry sheets above.
A47: Dashboard_PARAKH contents | B47: 1) Overall PARAKH mastery by district (Foundational/Preparatory/Middle + combined). 2) Subject-wise mastery heat-map. 3) Boys vs Girls performance & gap. 4) Rural vs Urban performance & gap. 5) Performance by school management type. 6) Performance by Social Group (SC/ST/OBC/General) with equity gaps. 7) Contextual Variables summary — High- vs Low-Performing schools, by questionnaire (School/Teacher/Pupil G3/G6/G9). Plus 4 charts visualising the above.
A49: 10. Combined_Performance_Ranking
A50: What to enter | B50: Only the two weight cells (B3, D3) if you want to change the default 50/50 weighting between PGI-D and PARAKH.
...

Sheet Districts_Setup
A1: Gujarat - All 33 Districts Covered in this Analysis
A2: Pre-filled with Gujarat's 33 districts (as per UDISE+/PARAKH administrative list). Edit names here ONLY if your dataset uses different district boundaries — every other sheet updates automatically.
A3: Si | B3: District Name | C3: Notes (optional)
A4: 1 | B4: Ahmedabad
A5: 2 | B5: Amreli
A6: 3 | B6: Anand
A7: 4 | B7: Aravalli
A8: 5 | B8: Banaskantha
A9: 6 | B9: Bharuch
A10: 7 | B10: Bhavnagar
A11: 8 | B11: Botad
A12: 9 | B12: Chhota Udepur
A13: 10 | B13: Dahod
A14: 11 | B14: Dang
A15: 12 | B15: Devbhoomi Dwarka
... A36: 33 | B36: Valsad

Sheet State_PGI_2.0
A1: Gujarat - State-level PGI 2.0 Data Entry (Annexure-3, Total 1000 points), Domain-wise
A2: Enter raw indicator scores. Domain totals, % Achieved and Grade calculate automatically. See column K for entry guidance.
A3: Domain | B3: Indicator # | C3: Indicator | D3: Data Source | E3: Weight | F3: 2022-23 | G3: 2023-24 | H3: 2024-25 | I3: % Achieved (2024-25) | J3: Grade (2024-25) | K3: How to Enter This Score
A4: Domain 1: Learning Outcomes and Quality (LO) - 240 | B4: 1.1 | C4: Learning Outcome in Language in Class 3 - All Schools | D4: PARAKH | E4: 30 | H4: 13.9 | I4: =IF(E4=0,0,H4/E4*100) -> 46.333333 | J4: =IFERROR(VLOOKUP(I4,Grading_Scale!$A$3:$B$12,2,TRUE()),"") -> Prachesta-2 | K4: Enter Gujarat's PARAKH-based score (0–30); higher = more students at/above grade-level proficiency. Source: PARAKH RS scorecard.
A5: Domain 1: Learning Outcomes and Quality (LO) - 240 | B5: 1.2 | C5: Learning Outcome in Mathematics in Class 3 - All Schools | D5: PARAKH | E5: 30 | H5: 11.5 | I5: =IF(E5=0,0,H5/E5*100) -> 38.333333 | J5: =IFERROR(VLOOKUP(I5,Grading_Scale!$A$3:$B$12,2,TRUE()),"") -> Prachesta-3
A6: Domain 1: Learning Outcomes and Quality (LO) - 240 | B6: 1.3 | C6: Learning Outcome in Language in Class 6 - All Schools | D6: PARAKH | E6: 30 | H6: 6.6 | I6: =IF(E6=0,0,H6/E6*100) -> 22 | J6: =IFERROR(VLOOKUP(I6,Grading_Scale!$A$3:$B$12,2,TRUE()),"") -> Akanshi-1
A7: Domain 1: Learning Outcomes and Quality (LO) - 240 | B7: 1.4 | C7: Learning Outcome in Mathematics in Class 6 - All Schools | D7: PARAKH | E7: 25 | H7: 5.9 | I7: =IF(E7=0,0,H7/E7*100) -> 23.6 | J7: =IFERROR(VLOOKUP(I7,Grading_Scale!$A$3:$B$12,2,TRUE()),"") -> Akanshi-1
A8: Domain 1: Learning Outcomes and Quality (LO) - 240 | B8: 1.5 | C8: Learning Outcome in TWAU (The World Around Us) in Class 6 - All Schools | D8: PARAKH | E8: 25 | H8: 6.6 | I8: =IF(E8=0,0,H8/E8*100) -> 26.4 | J8: =IFERROR(VLOOKUP(I8,Grading_Scale!$A$3:$B$12,2,TRUE()),"") -> Akanshi-1
A9: Domain 1: Learning Outcomes and Quality (LO) - 240 | B9: 1.6 | C9: Learning Outcome in Language in Class 9 - All Schools | D9: PARAKH | E9: 25 | H9: 6 | I9: =IF(E9=0,0,H9/E9*100) -> 24 | J9: =IFERROR(VLOOKUP(I9,Grading_Scale!$A$3:$B$12,2,TRUE()),"") -> Akanshi-1
A10: Domain 1: Learning Outcomes and Quality (LO) - 240 | B10: 1.7 | C10: Learning Outcome in Mathematics in Class 9 - All Schools | D10: PARAKH | E10: 25 | H10: 0.9 | I10: =IF(E10=0,0,H10/E10*100) -> 3.6 | J10: =IFERROR(VLOOKUP(I10,Grading_Scale!$A$3:$B$12,2,TRUE()),"") -> Akanshi-3
A11: Domain 1: Learning Outcomes and Quality (LO) - 240 | B11: 1.8 | C11: Learning Outcome in Science in Class 9 - All Schools | D11: PARAKH | E11: 25 | H11: 2.1 | I11: =IF(E11=0,0,H11/E11*100) -> 8.4 | J11: =IFERROR(VLOOKUP(I11,Grading_Scale!$A$3:$B$12,2,TRUE()),"") -> Akanshi-3
A12: Domain 1: Learning Outcomes and Quality (LO) - 240 | B12: 1.9 | C12: Learning Outcome in Social Science in Class 9 - All Schools | D12: PARAKH | E12: 25 | H12: 5 | I12: =IF(E12=0,0,H12/E12*100) -> 20 | J12: =IFERROR(VLOOKUP(I12,Grading_Scale!$A$3:$B$12,2,TRUE()),"") -> Akanshi-2
A13: Domain 2: Access (A) - 80 | B13: 2.1 | C13: Adjusted NER at Secondary level (All Schools) | D13: UDISE+ | E13: 10 | H13: 6.4 | I13: =IF(E13=0,0,H13/E13*100) -> 64 | J13: =IFERROR(VLOOKUP(I13,Grading_Scale!$A$3:$B$12,2,TRUE()),"") -> Uttam
A14: Domain 2: Access (A) - 80 | B14: 2.2 | C14: NER at Higher Secondary level (11-12) (All Schools) | D14: UDISE+ | E14: 10 | H14: 2.4 | I14: =IF(E14=0,0,H14/E14*100) -> 24 | J14: =IFERROR(VLOOKUP(I14,Grading_Scale!$A$3:$B$12,2,TRUE()),"") -> Akanshi-1
A15: Domain 2: Access (A) - 80 | B15: 2.3 | C15: Retention rate at Primary level (All Schools) | D15: UDISE+ | E15: 10 | H15: 10 | I15: =IF(E15=0,0,H15/E15*100) -> 100 | J15: =IFERROR(VLOOKUP(I15,Grading_Scale!$A$3:$B$12,2,TRUE()),"") -> Daksh
A16: Domain 2: Access (A) - 80 | B16: 2.4 | C16: Retention rate at Upper Primary level (All Schools) | D16: UDISE+ | E16: 10 | H16: 9.1 | I16: =IF(E16=0,0,H16/E16*100) -> 91 | J16: =IFERROR(VLOOKUP(I16,Grading_Scale!$A$3:$B$12,2,TRUE()),"") -> Utkarsh
... A104: Domain 6: Teacher Education & Training (TE&T) - 100 | B104: 6.8 | C104: Proportion of teachers with minimal professional qualifications - Higher Secondary | D104: UDISE+ | E104: 15 | H104: 14.5 | I104: =IF(E104=0,0,H104/E104*100) -> 96.666667 | J104: =IFERROR(VLOOKUP(I104,Grading_Scale!$A$3:$B$12,2,TRUE()),"") -> Daksh
A106: DOMAIN-WISE SUMMARY — GUJARAT STATE
A107: Domain | B107: Max Weight | C107: 2022-23 | D107: 2023-24 | E107: 2024-25 | F107: % Achieved (2024-25) | G107: Grade (2024-25)
A108: Domain 1: Learning Outcomes and Quality (LO) - 240 | B108: =SUM(E4:E12) -> 240 | C108: =SUM(F4:F12) -> 0 | D108: =SUM(G4:G12) -> 0 | E108: =SUM(H4:H12) -> 58.5 | F108: =IF(B108=0,0,E108/B108*100) -> 24.375 | G108: =IFERROR(VLOOKUP(F108,Grading_Scale!$A$3:$B$12,2,TRUE()),"") -> Akanshi-1
A109: Domain 2: Access (A) - 80 | B109: =SUM(E13:E20) -> 80 | C109: =SUM(F13:F20) -> 0 | D109: =SUM(G13:G20) -> 0 | E109: =SUM(H13:H20) -> 62.4 | F109: =IF(B109=0,0,E109/B109*100) -> 78 | G109: =IFERROR(VLOOKUP(F109,Grading_Scale!$A$3:$B$12,2,TRUE()),"") -> Atti-Uttam
A110: Domain 3: Infrastructure & Facilities (I&F) - 190 | B110: =SUM(E21:E44) -> 190 | C110: =SUM(F21:F44) -> 0 | D110: =SUM(G21:G44) -> 0 | E110: =SUM(H21:H44) -> 81.37 | F110: =IF(B110=0,0,E110/B110*100) -> 42.826316 | G110: =IFERROR(VLOOKUP(F110,Grading_Scale!$A$3:$B$12,2,TRUE()),"") -> Prachesta-2
A111: Domain 4: Equity (E) - 260 | B111: =SUM(E45:E80) -> 260 | C111: =SUM(F45:F80) -> 0 | D111: =SUM(G45:G80) -> 0 | E111: =SUM(H45:H80) -> 228 | F111: =IF(B111=0,0,E111/B111*100) -> 87.692308 | G111: =IFERROR(VLOOKUP(F111,Grading_Scale!$A$3:$B$12,2,TRUE()),"") -> Utkarsh
A112: Domain 5: Governance Processes (GP) - 130 | B112: =SUM(E81:E96) -> 130 | C112: =SUM(F81:F96) -> 0 | D112: =SUM(G81:G96) -> 0 | E112: =SUM(H81:H96) -> 78.4 | F112: =IF(B112=0,0,E112/B112*100) -> 60.307692 | G112: =IFERROR(VLOOKUP(F112,Grading_Scale!$A$3:$B$12,2,TRUE()),"") -> Prachesta-1
A113: Domain 6: Teacher Education & Training (TE&T) - 100 | B113: =SUM(E97:E104) -> 100 | C113: =SUM(F97:F104) -> 0 | D113: =SUM(G97:G104) -> 0 | E113: =SUM(H97:H104) -> 74.2 | F113: =IF(B113=0,0,E113/B113*100) -> 74.2 | G113: =IFERROR(VLOOKUP(F113,Grading_Scale!$A$3:$B$12,2,TRUE()),"") -> Atti-Uttam
A114: GUJARAT STATE — OVERALL PGI 2.0 SCORE | B114: =SUM(B108:B113) -> 1000 | C114: =SUM(C108:C113) -> 0 | D114: =SUM(D108:D113) -> 0 | E114: =SUM(E108:E113) -> 582.87 | F114: =IF(B114=0,0,E114/B114*100) -> 58.287 | G114: =IFERROR(VLOOKUP(F114,Grading_Scale!$A$3:$B$12,2,TRUE()),"") -> Prachesta-1

Sheet District_PGI-D_600
A1: Gujarat - District-wise PGI-D 2.0 Data Entry (Annexure-2, Total 600 points), All 33 Districts
A2: Enter raw indicator scores per district (blue cells). Category & Domain totals, % Achieved and Grade calculate automatically. District names pulled from Districts_Setup. See last column for entry guidance.
A3: Category | B3: Domain | C3: Ind. No. | D3: Indicator | E3: Data Source | F3: Weight | G3: =Districts_Setup!$B$4 -> Ahmedabad | H3: =Districts_Setup!$B$5 -> Amreli | I3: =Districts_Setup!$B$6 -> Anand | J3: =Districts_Setup!$B$7 -> Aravalli | K3: =Districts_Setup!$B$8 -> Banaskantha | L3: =Districts_Setup!$B$9 -> Bharuch | M3: =Districts_Setup!$B$10 -> Bhavnagar | N3: =Districts_Setup!$B$11 -> Botad | O3: =Districts_Setup!$B$12 -> Chhota Udepur | P3: =Districts_Setup!$B$13 -> Dahod | Q3: =Districts_Setup!$B$14 -> Dang | R3: =Districts_Setup!$B$15 -> Devbhoomi Dwarka | S3: =Districts_Setup!$B$16 -> Gandhinagar | T3: =Districts_Setup!$B$17 -> Gir Somnath | U3: =Districts_Setup!$B$18 -> Jamnagar | V3: =Districts_Setup!$B$19 -> Junagadh | W3: =Districts_Setup!$B$20 -> Kutch | X3: =Districts_Setup!$B$21 -> Kheda | Y3: =Districts_Setup!$B$22 -> Mahisagar | Z3: =Districts_Setup!$B$23 -> Mehsana | AA3: =Districts_Setup!$B$24 -> Morbi | AB3: =Districts_Setup!$B$25 -> Narmada | AC3: =Districts_Setup!$B$26 -> Navsari | AD3: =Districts_Setup!$B$27 -> Panchmahal | AE3: =Districts_Setup!$B$28 -> Patan | AF3: =Districts_Setup!$B$29 -> Porbandar | AG3: =Districts_Setup!$B$30 -> Rajkot | AH3: =Districts_Setup!$B$31 -> Sabarkantha | AI3: =Districts_Setup!$B$32 -> Surat | AJ3: =Districts_Setup!$B$33 -> Surendranagar | AK3: =Districts_Setup!$B$34 -> Tapi | AL3: =Districts_Setup!$B$35 -> Vadodara | AM3: =Districts_Setup!$B$36 -> Valsad | AN3: State Avg (33 Districts) | AO3: How to Enter This Score
A4: Category 1: Outcomes (290) | B4: 1.1 Learning Outcomes & Quality (LOQ) | C4: 1.1.1 | D4: % of children in Grade 3 who have achieved minimum proficiency in Language | E4: PRS/Parakh | F4: 20 | G4: 10.4 | H4: 8.47 | I4: 9.72 | J4: 7.72 | K4: 8.18 | L4: 9.62 | M4: 11.55 | N4: 9.76 | O4: 7.8 | P4: 10.56 | Q4: 10.69 | R4: 8.88 | S4: 11.65 | T4: 6.39 | U4: 5.78 | V4: 8.91 | W4: 7.62 | X4: 7.85 | Y4: 10.26 | Z4: 9.67 | AA4: 9.87 | AB4: 10.01 | AC4: 8.87 | AD4: 10.44 | AE4: 7.87 | AF4: 6.99 | AG4: 9.29 | AH4: 11.75 | AI4: 8.85 | AJ4: 10.61 | AK4: 10.88 | AL4: 7.65 | AM4: 9.77 | AN4: =IFERROR(AVERAGE(G4:AM4),0) -> 9.2221212 | AO4: Enter the score (0–20) awarded for this indicator under PGI-D, from RPS/NAS, UDISE+ or PRABANDH as shown in 'Data Source'.
A5: Category 1: Outcomes (290) | B5: 1.1 Learning Outcomes & Quality (LOQ) | C5: 1.1.2 | D5: % of children in Grade 3 who have achieved minimum proficiency in Mathematics | E5: PRS/Parakh | F5: 20 | G5: 9.12 | H5: 7.04 | I5: 7.62 | J5: 6.16 | K5: 6.44 | L5: 8 | M5: 10.07 | N5: 7.71 | O5: 6.51 | P5: 9.14 | Q5: 9.18 | R5: 7.38 | S5: 10.44 | T5: 5.24 | U5: 4.26 | V5: 6.67 | W5: 6.12 | X5: 6.14 | Y5: 8.23 | Z5: 8.07 | AA5: 7.88 | AB5: 8.46 | AC5: 6.97 | AD5: 9 | AE5: 6.23 | AF5: 5.39 | AG5: 7.56 | AH5: 10.74 | AI5: 6.87 | AJ5: 8.71 | AK5: 9.45 | AL5: 5.9 | AM5: 8.38 | AN5: =IFERROR(AVERAGE(G5:AM5),0) -> 7.6084848
A6: Category 1: Outcomes (290) | B6: 1.1 Learning Outcomes & Quality (LOQ) | C6: 1.1.3 | D6: % of children in Grade 6 who have achieved Grade level proficiency in Language | E6: PRS/Parakh | F6: 20 | G6: 4.3 | H6: 3.34 | I6: 4.89 | J6: 3.52 | K6: 4.29 | L6: 2.71 | M6: 4.55 | N6: 3.31 | O6: 2.94 | P6: 4.45 | Q6: 5.34 | R6: 5.61 | S6: 5.2 | T6: 3 | U6: 4.03 | V6: 5.17 | W6: 4.61 | X6: 3.32 | Y6: 3.55 | Z6: 4.62 | AA6: 3.96 | AB6: 3.51 | AC6: 4.04 | AD6: 4.64 | AE6: 4.64 | AF6: 4.21 | AG6: 4.04 | AH6: 3.84 | AI6: 5.18 | AJ6: 5.31 | AK6: 4.94 | AL6: 5.13 | AM6: 4.28 | AN6: =IFERROR(AVERAGE(G6:AM6),0) -> 4.2566667
A7: Category 1: Outcomes (290) | B7: 1.1 Learning Outcomes & Quality (LOQ) | C7: 1.1.4 | D7: % of children in Grade 6 who have achieved Grade level proficiency in Mathematics | E7: PRS/Parakh | F7: 20 | G7: 4.79 | H7: 2.72 | I7: 4.82 | J7: 3.54 | K7: 4.59 | L7: 2.88 | M7: 4.05 | N7: 3.55 | O7: 2.48 | P7: 5.54 | Q7: 3.31 | R7: 5.29 | S7: 5.65 | T7: 4.52 | U7: 4.32 | V7: 5.79 | W7: 4.54 | X7: 2.84 | Y7: 5.03 | Z7: 5.21 | AA7: 4.81 | AB7: 3.76 | AC7: 3.95 | AD7: 5.36 | AE7: 4.81 | AF7: 3.47 | AG7: 4.84 | AH7: 4.43 | AI7: 5.53 | AJ7: 5.92 | AK7: 5.08 | AL7: 5.24 | AM7: 4.22 | AN7: =IFERROR(AVERAGE(G7:AM7),0) -> 4.4509091
A8: Category 1: Outcomes (290) | B8: 1.1 Learning Outcomes & Quality (LOQ) | C8: 1.1.5 | D8: % of children in Grade 6 who have achieved Grade level proficiency in The World Around Us | E8: PRS/Parakh | F8: 20 | G8: 5.53 | H8: 3.92 | I8: 5.64 | J8: 4.31 | K8: 5.18 | L8: 3.49 | M8: 5.43 | N8: 4 | O8: 3.72 | P8: 5.63 | Q8: 6.07 | R8: 6.16 | S8: 6.47 | T8: 3.82 | U8: 5.25 | V8: 5.97 | W8: 5.2 | X8: 4.34 | Y8: 4.76 | Z8: 5.55 | AA8: 4.85 | AB8: 4.39 | AC8: 5.12 | AD8: 5.63 | AE8: 5.58 | AF8: 5.15 | AG8: 5.06 | AH8: 4.86 | AI8: 6.01 | AJ8: 6.49 | AK8: 6.36 | AL8: 5.87 | AM8: 4.77 | AN8: =IFERROR(AVERAGE(G8:AM8),0) -> 5.1690909
A9: Category 1: Outcomes (290) | B9: 1.1 Learning Outcomes & Quality (LOQ) | C9: 1.1.6 | D9: % of children in Grade 9 who have achieved Grade level proficiency in Language | E9: PRS/Parakh | F9: 20 | G9: 4.27 | H9: 3.86 | I9: 4.26 | J9: 3.23 | K9: 4.36 | L9: 4.8 | M9: 5.64 | N9: 3.55 | O9: 2.72 | P9: 1.88 | Q9: 2.79 | R9: 5.93 | S9: 7.67 | T9: 3.55 | U9: 5.54 | V9: 5.1 | W9: 5.88 | X9: 3.39 | Y9: 3.25 | Z9: 4.51 | AA9: 4.08 | AB9: 4.36 | AC9: 6.07 | AD9: 3.13 | AE9: 4.37 | AF9: 4.25 | AG9: 5.96 | AH9: 4.33 | AI9: 6.49 | AJ9: 3.58 | AK9: 5.37 | AL9: 6.86 | AM9: 5.37 | AN9: =IFERROR(AVERAGE(G9:AM9),0) -> 4.5575758
A10: Category 1: Outcomes (290) | B10: 1.1 Learning Outcomes & Quality (LOQ) | C10: 1.1.7 | D10: % of children in Grade 9 who have achieved Grade level proficiency in Mathematics | E10: PRS/Parakh | F10: 20 | G10: 0.91 | H10: 0.23 | I10: 0.34 | J10: 0.22 | K10: 0.35 | L10: 0.93 | M10: 0.3 | N10: 0.11 | O10: 0.14 | P10: 0.32 | Q10: 0.03 | R10: 0.34 | S10: 1.39 | T10: 0.47 | U10: 0.77 | V10: 0.41 | W10: 0.99 | X10: 0.31 | Y10: 0.29 | Z10: 0.6 | AA10: 0.14 | AB10: 0.15 | AC10: 0.71 | AD10: 0.26 | AE10: 0.6 | AF10: 0.21 | AG10: 0.83 | AH10: 0.52 | AI10: 1.23 | AJ10: 0.34 | AK10: 0.35 | AL10: 1.89 | AM10: 0.81 | AN10: =IFERROR(AVERAGE(G10:AM10),0) -> 0.53
A11: Category 1: Outcomes (290) | B11: 1.1 Learning Outcomes & Quality (LOQ) | C11: 1.1.8 | D11: % of children in Grade 9 who have achieved Grade level proficiency in Science | E11: PRS/Parakh | F11: 20 | G11: 1.82 | H11: 0.78 | I11: 1.22 | J11: 0.87 | K11: 0.96 | L11: 1.79 | M11: 1.37 | N11: 0.66 | O11: 0.47 | P11: 0.57 | Q11: 0.3 | R11: 1.48 | S11: 3.14 | T11: 1.22 | U11: 1.9 | V11: 1.49 | W11: 2.3 | X11: 0.88 | Y11: 0.79 | Z11: 1.49 | AA11: 0.76 | AB11: 0.84 | AC11: 2.16 | AD11: 0.81 | AE11: 1.47 | AF11: 0.84 | AG11: 2.02 | AH11: 1.25 | AI11: 2.49 | AJ11: 0.96 | AK11: 1.43 | AL11: 3.49 | AM11: 2.29 | AN11: =IFERROR(AVERAGE(G11:AM11),0) -> 1.4033333
A12: Category 1: Outcomes (290) | B12: 1.1 Learning Outcomes & Quality (LOQ) | C12: 1.1.9 | D12: % of children in Grade 9 who have achieved Grade level proficiency in Social Science | E12: PRS/Parakh | F12: 20 | G12: 3.33 | H12: 3.58 | I12: 3.23 | J12: 2.56 | K12: 3.46 | L12: 3.8 | M12: 4.96 | N12: 3.06 | O12: 2.4 | P12: 1.41 | Q12: 2.59 | R12: 4.86 | S12: 6.56 | T12: 2.92 | U12: 4.67 | V12: 4.54 | W12: 4.47 | X12: 2.55 | Y12: 2.17 | Z12: 3.76 | AA12: 3.43 | AB12: 3.09 | AC12: 5.06 | AD12: 2.54 | AE12: 3.58 | AF12: 3.15 | AG12: 5.09 | AH12: 3.49 | AI12: 5.56 | AJ12: 2.93 | AK12: 4.37 | AL12: 5.83 | AM12: 4.6 | AN12: =IFERROR(AVERAGE(G12:AM12),0) -> 3.7454545
A13: Category 1: Outcomes (290) | B13: 1.2 Access Outcomes (AO) | C13: 1.2.1 | D13: % of children in Grade 1 who have attended at least one year of pre-primary schooling | E13: UDISE+ | F13: 20 | G13: 17.43 | H13: 18.99 | I13: 19.29 | J13: 18.65 | K13: 18.57 | L13: 18.52 | M13: 18.8 | N13: 19.31 | O13: 18.75 | P13: 18.37 | Q13: 19.66 | R13: 18.68 | S13: 17.75 | T13: 19.2 | U13: 17.59 | V13: 18.94 | W13: 18.11 | X13: 19.25 | Y13: 19.14 | Z13: 18.8 | AA13: 18 | AB13: 19.37 | AC13: 19.34 | AD13: 19.15 | AE13: 18.77 | AF13: 18.67 | AG13: 17.96 | AH13: 18.43 | AI13: 17.54 | AJ13: 18.99 | AK13: 19.12 | AL13: 18.44 | AM13: 18.76 | AN13: =IFERROR(AVERAGE(G13:AM13),0) -> 18.67697
A14: Category 1: Outcomes (290) | B14: 1.2 Access Outcomes (AO) | C14: 1.2.3 | D14: Transition Rate from : 1. Primary to Upper Primary (Class 5 to Class 6) | E14: UDISE+ | F14: 5 | G14: 4.82 | H14: 4.83 | I14: 4.86 | J14: 4.87 | K14: 4.47 | L14: 4.81 | M14: 4.74 | N14: 4.86 | O14: 4.43 | P14: 4.58 | Q14: 4.53 | R14: 4.72 | S14: 4.94 | T14: 4.83 | U14: 4.77 | V14: 4.99 | W14: 4.44 | X14: 4.9 | Y14: 4.88 | Z14: 4.84 | AA14: 4.82 | AB14: 4.73 | AC14: 4.91 | AD14: 4.85 | AE14: 4.47 | AF14: 4.98 | AG14: 4.85 | AH14: 4.83 | AI14: 4.84 | AJ14: 4.7 | AK14: 4.81 | AL14: 4.91 | AM14: 4.74 | AN14: =IFERROR(AVERAGE(G14:AM14),0) -> 4.7742424
A15: Category 1: Outcomes (290) | B15: 1.2 Access Outcomes (AO) | C15: 1.2.4 | D15: Transition Rate from : 2. Upper Primary to Secondary (Class 8 to Class 9) | E15: UDISE+ | F15: 5 | G15: 4.23 | H15: 4.11 | I15: 4.39 | J15: 4.58 | K15: 3.86 | L15: 4.38 | M15: 4.29 | N15: 4.16 | O15: 3.87 | P15: 3.92 | Q15: 3.38 | R15: 3.81 | S15: 5 | T15: 4.19 | U15: 4.11 | V15: 4.74 | W15: 3.48 | X15: 4.38 | Y15: 4.61 | Z15: 4.5 | AA15: 4.11 | AB15: 3.99 | AC15: 5 | AD15: 4.21 | AE15: 3.85 | AF15: 4.43 | AG15: 4.55 | AH15: 4.2 | AI15: 4.43 | AJ15: 3.74 | AK15: 3.77 | AL15: 4.5 | AM15: 4.17 | AN15: =IFERROR(AVERAGE(G15:AM15),0) -> 4.210303
A16: Category 1: Outcomes (290) | B16: 1.2 Access Outcomes (AO) | C16: 1.2.5 | D16: Retention Rate till Elementary Level (New enrollment in Class 8 in year t+7 / Enrollment in Class 1 in year t) | E16: UDISE+ | F16: 10 | G16: 9.14 | H16: 8.86 | I16: 9.75 | J16: 9.72 | K16: 8.57 | L16: 9.21 | M16: 8.97 | N16: 9.71 | O16: 7.92 | P16: 8.01 | Q16: 8.07 | R16: 8.71 | S16: 9.45 | T16: 9.12 | U16: 8.36 | V16: 9.75 | W16: 8.29 | X16: 9.68 | Y16: 9.53 | Z16: 9.41 | AA16: 8.7 | AB16: 8.99 | AC16: 9.67 | AD16: 9.58 | AE16: 9.04 | AF16: 8.66 | AG16: 8.79 | AH16: 8.88 | AI16: 9.34 | AJ16: 8.64 | AK16: 9.54 | AL16: 9.59 | AM16: 8.97 | AN16: =IFERROR(AVERAGE(G16:AM16),0) -> 9.0490909
... A43: Category 2: Effective Classroom Transaction (90) | B43: 2.2 Learning Enrichment Activities (LEA) | C43: 2.2.11 | D43: School Development and Management Committee have been Constituted as per Samagra Shiksha guidelines | E43: UDISE+ | F43: 4 | G43: 0.63 | H43: 0.4 | I43: 0.4 | J43: 0.31 | K43: 0.34 | L43: 0.44 | M43: 0.44 | N43: 0.71 | O43: 0.29 | P43: 0.38 | Q43: 0.48 | R43: 0.41 | S43: 0.4 | T43: 0.41 | U43: 0.36 | V43: 0.45 | W43: 0.46 | X43: 0.28 | Y43: 0.39 | Z43: 0.49 | AA43: 0.44 | AB43: 0.48 | AC43: 0.26 | AD43: 0.31 | AE43: 0.44 | AF43: 0.45 | AG43: 0.42 | AH43: 0.56 | AI43: 0.33 | AJ43: 0.53 | AK43: 0.37 | AL43: 0.41 | AM43: 0.44 | AN43: =IFERROR(AVERAGE(G43:AM43),0) -> 0.42151515
A44: Category 3: Infrastructure, Facilities & Student Entitlements (51) | B44: 3. Infrastructure & Entitlements | C44: 3.1 | D44: % of Elementary Level schools getting Free Textbooks within one month of start of academic year | E44: UDISE+ | F44: 10 | G44: 9.36 | H44: 9.73 | I44: 9.8 | J44: 9.73 | K44: 9.78 | L44: 9.65 | M44: 9.64 | N44: 9.4 | O44: 9.15 | P44: 9.43 | Q44: 9.58 | R44: 9.46 | S44: 9.6 | T44: 9.82 | U44: 9.5 | V44: 9.67 | W44: 9.53 | X44: 9.68 | Y44: 9.68 | Z44: 9.76 | AA44: 9.73 | AB44: 9.66 | AC44: 9.86 | AD44: 9.75 | AE44: 9.78 | AF44: 9.61 | AG44: 9.66 | AH44: 9.79 | AI44: 9.49 | AJ44: 9.69 | AK44: 9.63 | AL44: 9.7 | AM44: 9.63 | AN44: =IFERROR(AVERAGE(G44:AM44),0) -> 9.6342424
A45: Category 3: Infrastructure, Facilities & Student Entitlements (51) | B45: 3. Infrastructure & Entitlements | C45: 3.2 | D45: % of Elementary Level Schools getting Uniforms within one month of the start of academic year | E45: UDISE+ | F45: 10 | G45: 5.23 | H45: 5.36 | I45: 6.1 | J45: 5.99 | K45: 5.2 | L45: 4.58 | M45: 4.83 | N45: 5.08 | O45: 5.38 | P45: 2.96 | Q45: 4.91 | R45: 5.21 | S45: 5.94 | T45: 5.99 | U45: 2.57 | V45: 5.3 | W45: 3.89 | X45: 5.44 | Y45: 5.16 | Z45: 5.58 | AA45: 5.2 | AB45: 6.19 | AC45: 4.71 | AD45: 4.26 | AE45: 5.65 | AF45: 4.85 | AG45: 4.83 | AH45: 6.18 | AI45: 5.07 | AJ45: 5.8 | AK45: 5.48 | AL45: 5.74 | AM45: 4.71 | AN45: =IFERROR(AVERAGE(G45:AM45),0) -> 5.1324242
A46: Category 3: Infrastructure, Facilities & Student Entitlements (51) | B46: 3. Infrastructure & Entitlements | C46: 3.3 | D46: % of entitled CWSN who have received aids and appliances (Govt. and aided schools) | E46: UDISE+ | F46: 5 | G46: 1.77 | H46: 1.57 | I46: 2.39 | J46: 1.99 | K46: 1.69 | L46: 2.09 | M46: 1.85 | N46: 3.14 | O46: 1.46 | P46: 1.27 | Q46: 1.37 | R46: 1.23 | S46: 2.05 | T46: 1.58 | U46: 2.45 | V46: 2.05 | W46: 1.86 | X46: 2.48 | Y46: 2.03 | Z46: 2.34 | AA46: 1.64 | AB46: 1.5 | AC46: 1.78 | AD46: 2.21 | AE46: 2.18 | AF46: 1.63 | AG46: 2.25 | AH46: 2.3 | AI46: 2.11 | AJ46: 2.05 | AK46: 2.61 | AL46: 2.27 | AM46: 1.76 | AN46: =IFERROR(AVERAGE(G46:AM46),0) -> 1.9681818
A47: Category 3: Infrastructure, Facilities & Student Entitlements (51) | B47: 3. Infrastructure & Entitlements | C47: 3.4 | D47: Library and/ or Reading Corner | E47: UDISE+ | F47: 4 | G47: 3.64 | H47: 3.89 | I47: 3.88 | J47: 3.98 | K47: 3.89 | L47: 3.83 | M47: 3.92 | N47: 3.93 | O47: 3.95 | P47: 3.88 | Q47: 3.94 | R47: 3.84 | S47: 3.73 | T47: 3.78 | U47: 3.73 | V47: 3.8 | W47: 3.87 | X47: 3.9 | Y47: 3.94 | Z47: 3.92 | AA47: 3.92 | AB47: 3.96 | AC47: 3.91 | AD47: 3.89 | AE47: 3.83 | AF47: 3.9 | AG47: 3.72 | AH47: 3.91 | AI47: 3.64 | AJ47: 3.83 | AK47: 3.95 | AL47: 3.94 | AM47: 3.8 | AN47: =IFERROR(AVERAGE(G47:AM47),0) -> 3.8618182
A48: Category 3: Infrastructure, Facilities & Student Entitlements (51) | B48: 3. Infrastructure & Entitlements | C48: 3.5 | D48: Ramp with railing | E48: UDISE+ | F48: 4 | G48: 2.24 | H48: 2.92 | I48: 2.48 | J48: 2.98 | K48: 2.73 | L48: 2.85 | M48: 2.52 | N48: 2.17 | O48: 2.83 | P48: 2.55 | Q48: 3.4 | R48: 2.7 | S48: 2.14 | T48: 2.16 | U48: 1.89 | V48: 2.3 | W48: 2.09 | X48: 2.77 | Y48: 2.75 | Z48: 2.58 | AA48: 2.32 | AB48: 2.39 | AC48: 3.15 | AD48: 2.59 | AE48: 2.92 | AF48: 2.73 | AG48: 1.91 | AH48: 2.55 | AI48: 1.82 | AJ48: 2.25 | AK48: 2.87 | AL48: 2.33 | AM48: 2.74 | AN48: =IFERROR(AVERAGE(G48:AM48),0) -> 2.5339394
A49: Category 3: Infrastructure, Facilities & Student Entitlements (51) | B49: 3. Infrastructure & Entitlements | C49: 3.6 | D49: Integrated Science laboratory | E49: UDISE+ | F49: 4 | G49: 1.74 | H49: 1.76 | I49: 2.41 | J49: 1.26 | K49: 1.6 | L49: 2.33 | M49: 1.79 | N49: 1.39 | O49: 1.74 | P49: 0.96 | Q49: 1.28 | R49: 1.6 | S49: 2.42 | T49: 1.5 | U49: 1.4 | V49: 1.58 | W49: 2.14 | X49: 1.79 | Y49: 1.6 | Z49: 2.63 | AA49: 1.92 | AB49: 1.47 | AC49: 2.44 | AD49: 1.33 | AE49: 2 | AF49: 1.5 | AG49: 1.96 | AH49: 1.94 | AI49: 2.09 | AJ49: 1.63 | AK49: 1.59 | AL49: 2.26 | AM49: 2.01 | AN49: =IFERROR(AVERAGE(G49:AM49),0) -> 1.789697
A50: Category 3: Infrastructure, Facilities & Student Entitlements (51) | B50: 3. Infrastructure & Entitlements | C50: 3.7 | D50: Kitchen Garden | E50: UDISE+ | F50: 4 | G50: 0.96 | H50: 2.11 | I50: 2.32 | J50: 2.75 | K50: 2.33 | L50: 2.05 | M50: 1.8 | N50: 2.24 | O50: 2.32 | P50: 2.16 | Q50: 3.48 | R50: 1.55 | S50: 1.77 | T50: 1.81 | U50: 0.88 | V50: 1.47 | W50: 1.89 | X50: 2.17 | Y50: 2.22 | Z50: 2.2 | AA50: 1.59 | AB50: 2.78 | AC50: 2.61 | AD50: 2.17 | AE50: 2.2 | AF50: 1.24 | AG50: 1.25 | AH50: 2.65 | AI50: 1.61 | AJ50: 1.48 | AK50: 3.31 | AL50: 1.36 | AM50: 2.69 | AN50: =IFERROR(AVERAGE(G50:AM50),0) -> 2.0430303
A51: Category 3: Infrastructure, Facilities & Student Entitlements (51) | B51: 3. Infrastructure & Entitlements | C51: 3.8 | D51: Library books | E51: UDISE+ | F51: 4 | G51: 3.62 | H51: 2.63 | I51: 2.74 | J51: 3.8 | K51: 3.63 | L51: 3.22 | M51: 3.86 | N51: 2.6 | O51: 2.61 | P51: 3.34 | Q51: 3.79 | R51: 3.92 | S51: 2.71 | T51: 2.92 | U51: 4 | V51: 3.91 | W51: 3.21 | X51: 4 | Y51: 3.95 | Z51: 3.96 | AA51: 3.94 | AB51: 4 | AC51: 3.87 | AD51: 3.95 | AE51: 2.89 | AF51: 3.55 | AG51: 3.6 | AH51: 3.9 | AI51: 3.37 | AJ51: 2.72 | AK51: 3.59 | AL51: 3.39 | AM51: 3.19 | AN51: =IFERROR(AVERAGE(G51:AM51),0) -> 3.4660606
A52: Category 3: Infrastructure, Facilities & Student Entitlements (51) | B52: 3. Infrastructure & Entitlements | C52: 3.9 | D52: Sports equipment | E52: UDISE+ | F52: 2 | G52: 1.94 | H52: 1.89 | I52: 1.9 | J52: 1.91 | K52: 1.91 | L52: 1.89 | M52: 1.84 | N52: 1.86 | O52: 1.88 | P52: 1.94 | Q52: 1.84 | R52: 1.83 | S52: 1.92 | T52: 1.93 | U52: 1.81 | V52: 1.86 | W52: 1.76 | X52: 1.96 | Y52: 1.91 | Z52: 1.91 | AA52: 1.94 | AB52: 1.9 | AC52: 1.83 | AD52: 1.91 | AE52: 1.91 | AF52: 1.96 | AG52: 1.84 | AH52: 1.89 | AI52: 1.94 | AJ52: 1.92 | AK52: 1.92 | AL52: 1.91 | AM52: 1.9 | AN52: =IFERROR(AVERAGE(G52:AM52),0) -> 1.8927273
A53: Category 3: Infrastructure, Facilities & Student Entitlements (51) | B53: 3. Infrastructure & Entitlements | C53: 3.1 | D53: Activities under composite school grant | E53: UDISE+ | F53: 2 | G53: 1.92 | H53: 1.58 | I53: 1.92 | J53: 1.81 | K53: 1.84 | L53: 1.66 | M53: 1.89 | N53: 1.86 | O53: 1.76 | P53: 1.87 | Q53: 1.8 | R53: 1.81 | S53: 1.94 | T53: 1.61 | U53: 1.79 | V53: 1.84 | W53: 1.77 | X53: 1.82 | Y53: 1.79 | Z53: 1.95 | AA53: 1.86 | AB53: 1.72 | AC53: 1.92 | AD53: 1.7 | AE53: 1.86 | AF53: 1.97 | AG53: 1.81 | AH53: 1.87 | AI53: 1.77 | AJ53: 1.88 | AK53: 1.97 | AL53: 1.95 | AM53: 1.68 | AN53: =IFERROR(AVERAGE(G53:AM53),0) -> 1.8239394
A54: Category 3: Infrastructure, Facilities & Student Entitlements (51) | B54: 3. Infrastructure & Entitlements | C54: 3.11 | D54: % of schools having Eco and Youth Club | E54: UDISE+ | F54: 2 | G54: 0.65 | H54: 1.08 | I54: 1.03 | J54: 1.24 | K54: 1.03 | L54: 0.98 | M54: 1.08 | N54: 1.1 | O54: 1 | P54: 0.84 | Q54: 1.06 | R54: 1.18 | S54: 0.7 | T54: 1.06 | U54: 0.88 | V54: 0.84 | W54: 0.98 | X54: 1.27 | Y54: 1.03 | Z54: 1.11 | AA54: 1.23 | AB54: 1.23 | AC54: 0.92 | AD54: 1.23 | AE54: 1.25 | AF54: 1.1 | AG54: 0.77 | AH54: 1.1 | AI54: 0.67 | AJ54: 1.25 | AK54: 1.04 | AL54: 1.01 | AM54: 0.96 | AN54: =IFERROR(AVERAGE(G54:AM54),0) -> 1.0272727
A55: Category 4: School Safety & Child Protection (35) | B55: 4. School Safety & Child Protection | C55: 4.1 | D55: % of schools has appointed any teacher as a first level counselor | E55: UDISE+ | F55: 5 | G55: 1.75 | H55: 1.55 | I55: 1.86 | J55: 1.54 | K55: 1.79 | L55: 1.54 | M55: 1.94 | N55: 2.02 | O55: 1.64 | P55: 1.61 | Q55: 1.29 | R55: 1.81 | S55: 1.85 | T55: 1.91 | U55: 1.56 | V55: 1.73 | W55: 1.57 | X55: 1.79 | Y55: 1.95 | Z55: 1.92 | AA55: 1.73 | AB55: 1.83 | AC55: 1.57 | AD55: 1.64 | AE55: 1.96 | AF55: 1.67 | AG55: 1.93 | AH55: 1.88 | AI55: 1.75 | AJ55: 2.29 | AK55: 1.75 | AL55: 1.61 | AM55: 1.58 | AN55: =IFERROR(AVERAGE(G55:AM55),0) -> 1.7518182
... A73: Category 6: Governance Processes (84) | B73: 6. Governance Processes | C73: 6.7 | D73: b. % of schools meeting head-teacher norms for Upper Primary level as per RTE | E73: UDISE+ | F73: 15 | G73: 10.99 | H73: 10.55 | I73: 12.45 | J73: 11.08 | K73: 11.37 | L73: 11.43 | M73: 11.7 | N73: 10.82 | O73: 11.59 | P73: 11.94 | Q73: 10.77 | R73: 12.46 | S73: 10.76 | T73: 12.53 | U73: 11.81 | V73: 13.63 | W73: 11.98 | X73: 12.26 | Y73: 12.15 | Z73: 12.41 | AA73: 11.59 | AB73: 12.34 | AC73: 13.63 | AD73: 11.8 | AE73: 11.75 | AF73: 12.89 | AG73: 11.38 | AH73: 11.46 | AI73: 11.9 | AJ73: 12.42 | AK73: 12.66 | AL73: 11.83 | AM73: 12.5 | AN73: =IFERROR(AVERAGE(G73:AM73),0) -> 11.903939
A75: DOMAIN & CATEGORY-WISE SUMMARY BY DISTRICT
A76: Category / Domain | F76: Max Weight | G76: =Districts_Setup!$B$4 -> Ahmedabad | H76: =Districts_Setup!$B$5 -> Amreli | I76: =Districts_Setup!$B$6 -> Anand | J76: =Districts_Setup!$B$7 -> Aravalli | K76: =Districts_Setup!$B$8 -> Banaskantha | L76: =Districts_Setup!$B$9 -> Bharuch | M76: =Districts_Setup!$B$10 -> Bhavnagar | N76: =Districts_Setup!$B$11 -> Botad | O76: =Districts_Setup!$B$12 -> Chhota Udepur | P76: =Districts_Setup!$B$13 -> Dahod | Q76: =Districts_Setup!$B$14 -> Dang | R76: =Districts_Setup!$B$15 -> Devbhoomi Dwarka | S76: =Districts_Setup!$B$16 -> Gandhinagar | T76: =Districts_Setup!$B$17 -> Gir Somnath | U76: =Districts_Setup!$B$18 -> Jamnagar | V76: =Districts_Setup!$B$19 -> Junagadh | W76: =Districts_Setup!$B$20 -> Kutch | X76: =Districts_Setup!$B$21 -> Kheda | Y76: =Districts_Setup!$B$22 -> Mahisagar | Z76: =Districts_Setup!$B$23 -> Mehsana | AA76: =Districts_Setup!$B$24 -> Morbi | AB76: =Districts_Setup!$B$25 -> Narmada | AC76: =Districts_Setup!$B$26 -> Navsari | AD76: =Districts_Setup!$B$27 -> Panchmahal | AE76: =Districts_Setup!$B$28 -> Patan | AF76: =Districts_Setup!$B$29 -> Porbandar | AG76: =Districts_Setup!$B$30 -> Rajkot | AH76: =Districts_Setup!$B$31 -> Sabarkantha | AI76: =Districts_Setup!$B$32 -> Surat | AJ76: =Districts_Setup!$B$33 -> Surendranagar | AK76: =Districts_Setup!$B$34 -> Tapi | AL76: =Districts_Setup!$B$35 -> Vadodara | AM76: =Districts_Setup!$B$36 -> Valsad | AN76: State Avg
A77: 1.1 Learning Outcomes & Quality (LOQ) | F77: =SUM(F4:F12) -> 180 | G77: =SUM(G4:G12) -> 44.47 | H77: =SUM(H4:H12) -> 33.94 | I77: =SUM(I4:I12) -> 41.74 | J77: =SUM(J4:J12) -> 32.13 | K77: =SUM(K4:K12) -> 37.81 | L77: =SUM(L4:L12) -> 38.02 | M77: =SUM(M4:M12) -> 47.92 | ... AM77: =SUM(AM4:AM12) -> 44.49 | AN77: =IFERROR(AVERAGE(G77:AM77),0) -> 40.943636
A78: 1.2 Access Outcomes (AO) | F78: =SUM(F13:F19) -> 65 | G78: =SUM(G13:G19) -> 55.39 | H78: =SUM(H13:H19) -> 54.41 | I78: =SUM(I13:I19) -> 58.22 | J78: =SUM(J13:J19) -> 59.15 | K78: =SUM(K13:K19) -> 51.98 | L78: =SUM(L13:L19) -> 56.83 | M78: =SUM(M13:M19) -> 55.12 | ... AM78: =SUM(AM13:AM19) -> 55.51 | AN78: =IFERROR(AVERAGE(G78:AM78),0) -> 55.172121
A79: 1.3 Teacher Availability & Professional Development (TAPDO) | F79: =SUM(F20:F24) -> 45 | G79: =SUM(G20:G24) -> 26.79 | H79: =SUM(H20:H24) -> 30.02 | I79: =SUM(I20:I24) -> 30.01 | J79: =SUM(J20:J24) -> 33.1 | K79: =SUM(K20:K24) -> 27.31 | L79: =SUM(L20:L24) -> 29.81 | M79: =SUM(M20:M24) -> 28.82 | ... AM79: =SUM(AM20:AM24) -> 31.33 | AN79: =IFERROR(AVERAGE(G79:AM79),0) -> 30.095152
A80: CATEGORY 1: OUTCOMES (290) — TOTAL | F80: =SUM(F77,F78,F79) -> 290 | G80: =SUM(G77,G78,G79) -> 126.65 | H80: =SUM(H77,H78,H79) -> 118.37 | I80: =SUM(I77,I78,I79) -> 129.97 | J80: =SUM(J77,J78,J79) -> 124.38 | K80: =SUM(K77,K78,K79) -> 117.1 | L80: =SUM(L77,L78,L79) -> 124.66 | M80: =SUM(M77,M78,M79) -> 131.86 | ... AM80: =SUM(AM77,AM78,AM79) -> 131.33 | AN80: =IFERROR(AVERAGE(G80:AM80),0) -> 126.21091
A81: 2.1 Learning Management (LM) | F81: =SUM(F25:F32) -> 60 | G81: =SUM(G25:G32) -> 36.16 | H81: =SUM(H25:H32) -> 46.65 | I81: =SUM(I25:I32) -> 46.86 | J81: =SUM(J25:J32) -> 47.96 | K81: =SUM(K25:K32) -> 47.7 | L81: =SUM(L25:L32) -> 43.87 | M81: =SUM(M25:M32) -> 44.97 | ... AM81: =SUM(AM25:AM32) -> 44.64 | AN81: =IFERROR(AVERAGE(G81:AM81),0) -> 45.384545
A82: 2.2 Learning Enrichment Activities (LEA) | F82: =SUM(F33:F43) -> 30 | G82: =SUM(G33:G43) -> 21.28 | H82: =SUM(H33:H43) -> 22.21 | I82: =SUM(I33:I43) -> 21.45 | J82: =SUM(J33:J43) -> 20.6 | K82: =SUM(K33:K43) -> 20.67 | L82: =SUM(L33:L43) -> 20.7 | M82: =SUM(M33:M43) -> 21.4 | ... AM82: =SUM(AM33:AM43) -> 21.25 | AN82: =IFERROR(AVERAGE(G82:AM82),0) -> 21.421818
A83: CATEGORY 2: EFFECTIVE CLASSROOM TRANSACTION (90) — TOTAL | F83: =SUM(F81,F82) -> 90 | G83: =SUM(G81,G82) -> 57.44 | H83: =SUM(H81,H82) -> 68.86 | I83: =SUM(I81,I82) -> 68.31 | J83: =SUM(J81,J82) -> 68.56 | K83: =SUM(K81,K82) -> 68.37 | L83: =SUM(L81,L82) -> 64.57 | M83: =SUM(M81,M82) -> 66.37 | ... AM83: =SUM(AM81,AM82) -> 65.89 | AN83: =IFERROR(AVERAGE(G83:AM83),0) -> 66.806364
A84: 3. Infrastructure & Entitlements | F84: =SUM(F44:F54) -> 51 | G84: =SUM(G44:G54) -> 33.07 | H84: =SUM(H44:H54) -> 34.52 | I84: =SUM(I44:I54) -> 36.97 | J84: =SUM(J44:J54) -> 37.44 | K84: =SUM(K44:K54) -> 35.63 | L84: =SUM(L44:L54) -> 35.13 | M84: =SUM(M44:M54) -> 35.02 | ... AM84: =SUM(AM44:AM54) -> 35.07 | AN84: =IFERROR(AVERAGE(G84:AM84),0) -> 35.173333
...

Sheet PARAKH_Foundational_G3
A1: Gujarat - PARAKH Learning Achievement: Foundational Stage (Grade 3) - All Competencies x All 33 Districts
A2: Enter the proportion of district students (0-1, e.g. 0.62 for 62%) who mastered each competency, from the PARAKH RS district-wise report (dashboard.parakh.ncert.gov.in). District Average and Gap vs National compute automatically.
A3: Subject | B3: Competency Code | C3: Competency Description | D3: National (Benchmark) | E3: =Districts_Setup!$B$4 -> Ahmedabad | F3: =Districts_Setup!$B$5 -> Amreli | G3: =Districts_Setup!$B$6 -> Anand | H3: =Districts_Setup!$B$7 -> Aravalli | I3: =Districts_Setup!$B$8 -> Banaskantha | J3: =Districts_Setup!$B$9 -> Bharuch | K3: =Districts_Setup!$B$10 -> Bhavnagar | L3: =Districts_Setup!$B$11 -> Botad | M3: =Districts_Setup!$B$12 -> Chhota Udepur | N3: =Districts_Setup!$B$13 -> Dahod | O3: =Districts_Setup!$B$14 -> Dang | P3: =Districts_Setup!$B$15 -> Devbhoomi Dwarka | Q3: =Districts_Setup!$B$16 -> Gandhinagar | R3: =Districts_Setup!$B$17 -> Gir Somnath | S3: =Districts_Setup!$B$18 -> Jamnagar | T3: =Districts_Setup!$B$19 -> Junagadh | U3: =Districts_Setup!$B$20 -> Kutch | V3: =Districts_Setup!$B$21 -> Kheda | W3: =Districts_Setup!$B$22 -> Mahisagar | X3: =Districts_Setup!$B$23 -> Mehsana | Y3: =Districts_Setup!$B$24 -> Morbi | Z3: =Districts_Setup!$B$25 -> Narmada | AA3: =Districts_Setup!$B$26 -> Navsari | AB3: =Districts_Setup!$B$27 -> Panchmahal | AC3: =Districts_Setup!$B$28 -> Patan | AD3: =Districts_Setup!$B$29 -> Porbandar | AE3: =Districts_Setup!$B$30 -> Rajkot | AF3: =Districts_Setup!$B$31 -> Sabarkantha | AG3: =Districts_Setup!$B$32 -> Surat | AH3: =Districts_Setup!$B$33 -> Surendranagar | AI3: =Districts_Setup!$B$34 -> Tapi | AJ3: =Districts_Setup!$B$35 -> Vadodara | AK3: =Districts_Setup!$B$36 -> Valsad | AL3: District Avg | AM3: How to Enter This Value
A4: Language | B4: C-9.7 | C4: Knows and uses enough words to carry out day-to-day interactions effectively and can guess the meaning of new words by using existing Vocabulary | D4: 0.67 | E4: 0.64 | F4: 0.6 | G4: 0.63 | H4: 0.56 | I4: 0.6 | J4: 0.63 | K4: 0.67 | L4: 0.63 | M4: 0.57 | N4: 0.64 | O4: 0.64 | P4: 0.63 | Q4: 0.67 | R4: 0.55 | S4: 0.54 | T4: 0.62 | U4: 0.56 | V4: 0.57 | W4: 0.63 | X4: 0.61 | Y4: 0.65 | Z4: 0.61 | AA4: 0.6 | AB4: 0.62 | AC4: 0.59 | AD4: 0.57 | AE4: 0.6 | AF4: 0.65 | AG4: 0.6 | AH4: 0.67 | AI4: 0.66 | AJ4: 0.56 | AK4: 0.63 | AL4: =IFERROR(AVERAGE(E4:AK4),0) -> 0.61212121 | AM4: Enter as a decimal 0-1 (e.g. 0.62 for 62%) of this district's tested students who mastered the competency.
B5: C-10.5 | C5: Reads short stories and comprehends their meaning - by identifying characters, storyline and what the author wants to say - on their own | D5: 0.6 | E5: 0.55 | F5: 0.51 | G5: 0.53 | H5: 0.47 | I5: 0.49 | J5: 0.54 | K5: 0.59 | L5: 0.53 | M5: 0.47 | N5: 0.54 | O5: 0.53 | P5: 0.53 | Q5: 0.61 | R5: 0.44 | S5: 0.43 | T5: 0.51 | U5: 0.46 | V5: 0.46 | W5: 0.53 | X5: 0.54 | Y5: 0.54 | Z5: 0.54 | AA5: 0.5 | AB5: 0.54 | AC5: 0.48 | AD5: 0.45 | AE5: 0.54 | AF5: 0.58 | AG5: 0.51 | AH5: 0.58 | AI5: 0.57 | AJ5: 0.48 | AK5: 0.55 | AL5: =IFERROR(AVERAGE(E5:AK5),0) -> 0.51878788
B6: C-10.7 | C6: Reads and comprehends the meaning of short news items, instructions and recipes, and publicity material | D6: 0.61 | E6: 0.58 | F6: 0.53 | G6: 0.56 | H6: 0.5 | I6: 0.52 | J6: 0.56 | K6: 0.61 | L6: 0.57 | M6: 0.47 | N6: 0.6 | O6: 0.6 | P6: 0.54 | Q6: 0.6 | R6: 0.49 | S6: 0.46 | T6: 0.57 | U6: 0.49 | V6: 0.49 | W6: 0.58 | X6: 0.55 | Y6: 0.58 | Z6: 0.57 | AA6: 0.53 | AB6: 0.57 | AC6: 0.51 | AD6: 0.48 | AE6: 0.55 | AF6: 0.61 | AG6: 0.53 | AH6: 0.58 | AI6: 0.61 | AJ6: 0.5 | AK6: 0.56 | AL6: =IFERROR(AVERAGE(E6:AK6),0) -> 0.5469697
A7: Mathematics | B7: C-8.1 | C7: Sorts objects into groups and sub-groups based on more than one property | D7: 0.68 | E7: 0.66 | F7: 0.6 | G7: 0.61 | H7: 0.58 | I7: 0.61 | J7: 0.62 | K7: 0.67 | L7: 0.64 | M7: 0.53 | N7: 0.64 | O7: 0.65 | P7: 0.63 | Q7: 0.71 | R7: 0.55 | S7: 0.55 | T7: 0.63 | U7: 0.6 | V7: 0.58 | W7: 0.64 | X7: 0.63 | Y7: 0.67 | Z7: 0.65 | AA7: 0.62 | AB7: 0.64 | AC7: 0.61 | AD7: 0.58 | AE7: 0.62 | AF7: 0.67 | AG7: 0.61 | AH7: 0.67 | AI7: 0.66 | AJ7: 0.62 | AK7: 0.64 | AL7: =IFERROR(AVERAGE(E7:AK7),0) -> 0.62393939
B8: C-8.2 | C8: Identifies and extends simple patterns in their surroundings, shapes, and numbers | D8: 0.69 | E8: 0.65 | F8: 0.6 | G8: 0.67 | H8: 0.59 | I8: 0.62 | J8: 0.66 | K8: 0.67 | L8: 0.65 | M8: 0.57 | N8: 0.62 | O8: 0.64 | P8: 0.65 | Q8: 0.72 | R8: 0.56 | S8: 0.59 | T8: 0.65 | U8: 0.62 | V8: 0.55 | W8: 0.58 | X8: 0.61 | Y8: 0.66 | Z8: 0.6 | AA8: 0.65 | AB8: 0.65 | AC8: 0.6 | AD8: 0.64 | AE8: 0.63 | AF8: 0.67 | AG8: 0.62 | AH8: 0.69 | AI8: 0.74 | AJ8: 0.6 | AK8: 0.67 | AL8: =IFERROR(AVERAGE(E8:AK8),0) -> 0.6330303
B9: C-8.4 | C9: Arranges numbers up to 99 in ascending and descending order | D9: 0.55 | E9: 0.49 | F9: 0.46 | G9: 0.45 | H9: 0.42 | I9: 0.5 | J9: 0.54 | K9: 0.55 | L9: 0.44 | M9: 0.44 | N9: 0.5 | O9: 0.52 | P9: 0.51 | Q9: 0.57 | R9: 0.4 | S9: 0.4 | T9: 0.48 | U9: 0.42 | V9: 0.38 | W9: 0.48 | X9: 0.5 | Y9: 0.47 | Z9: 0.49 | AA9: 0.45 | AB9: 0.49 | AC9: 0.42 | AD9: 0.46 | AE9: 0.48 | AF9: 0.54 | AG9: 0.46 | AH9: 0.54 | AI9: 0.59 | AJ9: 0.41 | AK9: 0.51 | AL9: =IFERROR(AVERAGE(E9:AK9),0) -> 0.47757576
B10: C-8.5 | C10: Recognises and uses numerals to represent quantities up to 99 with the understanding of decimal place value system | D10: 0.61 | E10: 0.56 | F10: 0.55 | G10: 0.59 | H10: 0.52 | I10: 0.53 | J10: 0.57 | K10: 0.59 | L10: 0.57 | M10: 0.48 | N10: 0.57 | O10: 0.58 | P10: 0.53 | Q10: 0.61 | R10: 0.47 | S10: 0.51 | T10: 0.54 | U10: 0.51 | V10: 0.48 | W10: 0.55 | X10: 0.58 | Y10: 0.57 | Z10: 0.53 | AA10: 0.54 | AB10: 0.56 | AC10: 0.54 | AD10: 0.46 | AE10: 0.54 | AF10: 0.58 | AG10: 0.55 | AH10: 0.59 | AI10: 0.62 | AJ10: 0.54 | AK10: 0.58 | AL10: =IFERROR(AVERAGE(E10:AK10),0) -> 0.54818182
B11: C-8.6 | C11: Performs addition and subtraction of 2-digit numbers fluently using flexible strategies of composition and decomposition of both numerical and word problems | D11: 0.58 | E11: 0.49 | F11: 0.45 | G11: 0.44 | H11: 0.45 | I11: 0.45 | J11: 0.48 | K11: 0.54 | L11: 0.48 | M11: 0.44 | N11: 0.51 | O11: 0.5 | P11: 0.49 | Q11: 0.54 | R11: 0.41 | S11: 0.4 | T11: 0.42 | U11: 0.43 | V11: 0.41 | W11: 0.5 | X11: 0.47 | Y11: 0.45 | Z11: 0.46 | AA11: 0.47 | AB11: 0.49 | AC11: 0.43 | AD11: 0.41 | AE11: 0.46 | AF11: 0.56 | AG11: 0.44 | AH11: 0.5 | AI11: 0.51 | AJ11: 0.44 | AK11: 0.48 | AL11: =IFERROR(AVERAGE(E11:AK11),0) -> 0.46666667
B12: C-8.7 | C12: Recognises multiplication as repeated addition and division as equal sharing | D12: 0.54 | E12: 0.46 | F12: 0.41 | G12: 0.42 | H12: 0.42 | I12: 0.4 | J12: 0.41 | K12: 0.47 | L12: 0.45 | M12: 0.41 | N12: 0.52 | O12: 0.5 | P12: 0.42 | Q12: 0.53 | R12: 0.4 | S12: 0.32 | T12: 0.41 | U12: 0.38 | V12: 0.39 | W12: 0.46 | X12: 0.45 | Y12: 0.44 | Z12: 0.46 | AA12: 0.4 | AB12: 0.49 | AC12: 0.43 | AD12: 0.43 | AE12: 0.44 | AF12: 0.54 | AG12: 0.38 | AH12: 0.44 | AI12: 0.5 | AJ12: 0.36 | AK12: 0.42 | AL12: =IFERROR(AVERAGE(E12:AK12),0) -> 0.43515152
B13: C-8.8 | C13: Recognises, makes, and classifies basic geometric shapes and their observable properties, and understands and explains the relative relation of objects in space | D13: 0.5 | E13: 0.43 | F13: 0.4 | G13: 0.37 | H13: 0.39 | I13: 0.38 | J13: 0.39 | K13: 0.44 | L13: 0.39 | M13: 0.38 | N13: 0.42 | O13: 0.49 | P13: 0.43 | Q13: 0.46 | R13: 0.35 | S13: 0.38 | T13: 0.37 | U13: 0.39 | V13: 0.32 | W13: 0.41 | X13: 0.37 | Y13: 0.35 | Z13: 0.39 | AA13: 0.41 | AB13: 0.46 | AC13: 0.34 | AD13: 0.34 | AE13: 0.44 | AF13: 0.43 | AG13: 0.37 | AH13: 0.42 | AI13: 0.42 | AJ13: 0.36 | AK13: 0.38 | AL13: =IFERROR(AVERAGE(E13:AK13),0) -> 0.39606061
B14: C-8.9 | C14: Selects appropriate tools and units to perform simple measurements of length, weight, and volume of objects in their immediate environment | D14: 0.62 | E14: 0.56 | F14: 0.51 | G14: 0.54 | H14: 0.47 | I14: 0.53 | J14: 0.55 | K14: 0.61 | L14: 0.55 | M14: 0.49 | N14: 0.54 | O14: 0.58 | P14: 0.51 | Q14: 0.62 | R14: 0.46 | S14: 0.47 | T14: 0.55 | U14: 0.5 | V14: 0.47 | W14: 0.5 | X14: 0.51 | Y14: 0.54 | Z14: 0.53 | AA14: 0.55 | AB14: 0.53 | AC14: 0.49 | AD14: 0.47 | AE14: 0.53 | AF14: 0.57 | AG14: 0.51 | AH14: 0.57 | AI14: 0.61 | AJ14: 0.48 | AK14: 0.58 | AL14: =IFERROR(AVERAGE(E14:AK14),0) -> 0.52969697
B15: C-8.10 | C15: Performs simple measurements of time in minutes, hours, day, weeks, and months | D15: 0.61 | E15: 0.56 | F15: 0.51 | G15: 0.53 | H15: 0.45 | I15: 0.45 | J15: 0.54 | K15: 0.58 | L15: 0.5 | M15: 0.45 | N15: 0.56 | O15: 0.54 | P15: 0.52 | Q15: 0.59 | R15: 0.45 | S15: 0.41 | T15: 0.5 | U15: 0.47 | V15: 0.49 | W15: 0.53 | X15: 0.55 | Y15: 0.56 | Z15: 0.52 | AA15: 0.51 | AB15: 0.56 | AC15: 0.46 | AD15: 0.48 | AE15: 0.53 | AF15: 0.61 | AG15: 0.53 | AH15: 0.54 | AI15: 0.56 | AJ15: 0.47 | AK15: 0.54 | AL15: =IFERROR(AVERAGE(E15:AK15),0) -> 0.51666667
B16: C-8.11 | C16: Performs simple transactions using money up to INR 100 | D16: 0.5 | E16: 0.44 | F16: 0.42 | G16: 0.4 | H16: 0.4 | I16: 0.38 | J16: 0.43 | K16: 0.46 | L16: 0.42 | M16: 0.41 | N16: 0.46 | O16: 0.49 | P16: 0.42 | Q16: 0.47 | R16: 0.38 | S16: 0.34 | T16: 0.38 | U16: 0.36 | V16: 0.38 | W16: 0.42 | X16: 0.42 | Y16: 0.42 | Z16: 0.45 | AA16: 0.38 | AB16: 0.43 | AC16: 0.39 | AD16: 0.36 | AE16: 0.41 | AF16: 0.52 | AG16: 0.4 | AH16: 0.46 | AI16: 0.47 | AJ16: 0.37 | AK16: 0.4 | AL16: =IFERROR(AVERAGE(E16:AK16),0) -> 0.41636364
B17: C-8.12 | C17: Develops adequate and appropriate vocabulary for comprehending and expressing concepts and procedures related to quantities, shapes, space, and measurements | D17: 0.55 | E17: 0.58 | F17: 0.52 | G17: 0.54 | H17: 0.47 | I17: 0.5 | J17: 0.49 | K17: 0.58 | L17: 0.55 | M17: 0.42 | N17: 0.53 | O17: 0.52 | P17: 0.51 | Q17: 0.55 | R17: 0.41 | S17: 0.42 | T17: 0.51 | U17: 0.46 | V17: 0.52 | W17: 0.51 | X17: 0.49 | Y17: 0.58 | Z17: 0.5 | AA17: 0.46 | AB17: 0.53 | AC17: 0.49 | AD17: 0.5 | AE17: 0.52 | AF17: 0.56 | AG17: 0.46 | AH17: 0.52 | AI17: 0.51 | AJ17: 0.48 | AK17: 0.52 | AL17: =IFERROR(AVERAGE(E17:AK17),0) -> 0.50636364
B18: C-8.13 | C18: Formulates and solves simple mathematical problems related to quantities, shapes, space, and measurements | D18: 0.55 | E18: 0.48 | F18: 0.42 | G18: 0.42 | H18: 0.43 | I18: 0.42 | J18: 0.49 | K18: 0.49 | L18: 0.43 | M18: 0.41 | N18: 0.51 | O18: 0.54 | P18: 0.45 | Q18: 0.53 | R18: 0.38 | S18: 0.38 | T18: 0.44 | U18: 0.43 | V18: 0.39 | W18: 0.4 | X18: 0.45 | Y18: 0.46 | Z18: 0.48 | AA18: 0.44 | AB18: 0.45 | AC18: 0.42 | AD18: 0.37 | AE18: 0.41 | AF18: 0.5 | AG18: 0.43 | AH18: 0.44 | AI18: 0.48 | AJ18: 0.41 | AK18: 0.44 | AL18: =IFERROR(AVERAGE(E18:AK18),0) -> 0.4430303
A20: SUBJECT-WISE AVERAGE MASTERY BY DISTRICT - Foundational Stage (Grade 3)
A21: Subject | E21: =Districts_Setup!$B$4 -> Ahmedabad | F21: =Districts_Setup!$B$5 -> Amreli | G21: =Districts_Setup!$B$6 -> Anand | H21: =Districts_Setup!$B$7 -> Aravalli | I21: =Districts_Setup!$B$8 -> Banaskantha | J21: =Districts_Setup!$B$9 -> Bharuch | K21: =Districts_Setup!$B$10 -> Bhavnagar | L21: =Districts_Setup!$B$11 -> Botad | M21: =Districts_Setup!$B$12 -> Chhota Udepur | N21: =Districts_Setup!$B$13 -> Dahod | O21: =Districts_Setup!$B$14 -> Dang | P21: =Districts_Setup!$B$15 -> Devbhoomi Dwarka | Q21: =Districts_Setup!$B$16 -> Gandhinagar | R21: =Districts_Setup!$B$17 -> Gir Somnath | S21: =Districts_Setup!$B$18 -> Jamnagar | T21: =Districts_Setup!$B$19 -> Junagadh | U21: =Districts_Setup!$B$20 -> Kutch | V21: =Districts_Setup!$B$21 -> Kheda | W21: =Districts_Setup!$B$22 -> Mahisagar | X21: =Districts_Setup!$B$23 -> Mehsana | Y21: =Districts_Setup!$B$24 -> Morbi | Z21: =Districts_Setup!$B$25 -> Narmada | AA21: =Districts_Setup!$B$26 -> Navsari | AB21: =Districts_Setup!$B$27 -> Panchmahal | AC21: =Districts_Setup!$B$28 -> Patan | AD21: =Districts_Setup!$B$29 -> Porbandar | AE21: =Districts_Setup!$B$30 -> Rajkot | AF21: =Districts_Setup!$B$31 -> Sabarkantha | AG21: =Districts_Setup!$B$32 -> Surat | AH21: =Districts_Setup!$B$33 -> Surendranagar | AI21: =Districts_Setup!$B$34 -> Tapi | AJ21: =Districts_Setup!$B$35 -> Vadodara | AK21: =Districts_Setup!$B$36 -> Valsad | AL21: National Avg
A22: Language | E22: =IFERROR(AVERAGE(E4:E6),0) -> 0.59 | F22: =IFERROR(AVERAGE(F4:F6),0) -> 0.54666667 | G22: =IFERROR(AVERAGE(G4:G6),0) -> 0.57333333 | H22: =IFERROR(AVERAGE(H4:H6),0) -> 0.51 | I22: =IFERROR(AVERAGE(I4:I6),0) -> 0.53666667 | J22: =IFERROR(AVERAGE(J4:J6),0) -> 0.57666667 | K22: =IFERROR(AVERAGE(K4:K6),0) -> 0.62333333 | L22: =IFERROR(AVERAGE(L4:L6),0) -> 0.57666667 | ... AK22: =IFERROR(AVERAGE(AK4:AK6),0) -> 0.58 | AL22: =IFERROR(AVERAGE(D4:D6),0) -> 0.62666667
A23: Mathematics | E23: =IFERROR(AVERAGE(E7:E18),0) -> 0.53 | F23: =IFERROR(AVERAGE(F7:F18),0) -> 0.4875 | G23: =IFERROR(AVERAGE(G7:G18),0) -> 0.49833333 | H23: =IFERROR(AVERAGE(H7:H18),0) -> 0.46583333 | I23: =IFERROR(AVERAGE(I7:I18),0) -> 0.48083333 | J23: =IFERROR(AVERAGE(J7:J18),0) -> 0.51416667 | K23: =IFERROR(AVERAGE(K7:K18),0) -> 0.55416667 | L23: =IFERROR(AVERAGE(L7:L18),0) -> 0.50583333 | ... AK23: =IFERROR(AVERAGE(AK7:AK18),0) -> 0.51333333 | AL23: =IFERROR(AVERAGE(D7:D18),0) -> 0.58166667
A24: OVERALL FOUNDATIONAL STAGE (GRADE 3) AVERAGE | E24: =IFERROR(AVERAGE(E22:E23),0) -> 0.56 | F24: =IFERROR(AVERAGE(F22:F23),0) -> 0.51708333 | G24: =IFERROR(AVERAGE(G22:G23),0) -> 0.53583333 | H24: =IFERROR(AVERAGE(H22:H23),0) -> 0.48791667 | I24: =IFERROR(AVERAGE(I22:I23),0) -> 0.50875 | J24: =IFERROR(AVERAGE(J22:J23),0) -> 0.54541667 | K24: =IFERROR(AVERAGE(K22:K23),0) -> 0.58875 | L24: =IFERROR(AVERAGE(L22:L23),0) -> 0.54125 | ... AL24: =IFERROR(AVERAGE(AL22:AL23),0) -> 0.60416667

Sheet PARAKH_Preparatory_G6
A1: Gujarat - PARAKH Learning Achievement: Preparatory Stage (Grade 6) - All Competencies x All 33 Districts
A2: Enter the proportion of district students (0-1, e.g. 0.62 for 62%) who mastered each competency, from the PARAKH RS district-wise report (dashboard.parakh.ncert.gov.in). District Average and Gap vs National compute automatically.
A3: Subject | B3: Competency Code | C3: Competency Description | D3: National (Benchmark) | E3: =Districts_Setup!$B$4 -> Ahmedabad | F3: =Districts_Setup!$B$5 -> Amreli | G3: =Districts_Setup!$B$6 -> Anand | H3: =Districts_Setup!$B$7 -> Aravalli | I3: =Districts_Setup!$B$8 -> Banaskantha | J3: =Districts_Setup!$B$9 -> Bharuch | K3: =Districts_Setup!$B$10 -> Bhavnagar | L3: =Districts_Setup!$B$11 -> Botad | M3: =Districts_Setup!$B$12 -> Chhota Udepur | N3: =Districts_Setup!$B$13 -> Dahod | O3: =Districts_Setup!$B$14 -> Dang | P3: =Districts_Setup!$B$15 -> Devbhoomi Dwarka | Q3: =Districts_Setup!$B$16 -> Gandhinagar | R3: =Districts_Setup!$B$17 -> Gir Somnath | S3: =Districts_Setup!$B$18 -> Jamnagar | T3: =Districts_Setup!$B$19 -> Junagadh | U3: =Districts_Setup!$B$20 -> Kutch | V3: =Districts_Setup!$B$21 -> Kheda | W3: =Districts_Setup!$B$22 -> Mahisagar | X3: =Districts_Setup!$B$23 -> Mehsana | Y3: =Districts_Setup!$B$24 -> Morbi | Z3: =Districts_Setup!$B$25 -> Narmada | AA3: =Districts_Setup!$B$26 -> Navsari | AB3: =Districts_Setup!$B$27 -> Panchmahal | AC3: =Districts_Setup!$B$28 -> Patan | AD3: =Districts_Setup!$B$29 -> Porbandar | AE3: =Districts_Setup!$B$30 -> Rajkot | AF3: =Districts_Setup!$B$31 -> Sabarkantha | AG3: =Districts_Setup!$B$32 -> Surat | AH3: =Districts_Setup!$B$33 -> Surendranagar | AI3: =Districts_Setup!$B$34 -> Tapi | AJ3: =Districts_Setup!$B$35 -> Vadodara | AK3: =Districts_Setup!$B$36 -> Valsad | AL3: District Avg | AM3: How to Enter This Value
A4: Language | B4: C-2.1 | C4: Applies varied comprehension strategies (inference, prediction, visualisation) to understand different texts | D4: 0.56 | E4: 0.5 | F4: 0.47 | G4: 0.52 | H4: 0.47 | I4: 0.51 | J4: 0.44 | K4: 0.51 | L4: 0.49 | M4: 0.44 | N4: 0.48 | O4: 0.53 | P4: 0.54 | Q4: 0.54 | R4: 0.44 | S4: 0.5 | T4: 0.54 | U4: 0.5 | V4: 0.47 | W4: 0.48 | X4: 0.53 | Y4: 0.49 | Z4: 0.48 | AA4: 0.5 | AB4: 0.5 | AC4: 0.51 | AD4: 0.49 | AE4: 0.48 | AF4: 0.48 | AG4: 0.53 | AH4: 0.56 | AI4: 0.52 | AJ4: 0.53 | AK4: 0.5 | AL4: =IFERROR(AVERAGE(E4:AK4),0) -> 0.49909091 | AM4: Enter as a decimal 0-1 (e.g. 0.62 for 62%) of this district's tested students who mastered the competency.
B5: C-2.2 | C5: Understands main ideas and draws essential conclusions from the material read | D5: 0.58 | E5: 0.53 | F5: 0.49 | G5: 0.55 | H5: 0.51 | I5: 0.54 | J5: 0.47 | K5: 0.54 | L5: 0.52 | M5: 0.46 | N5: 0.5 | O5: 0.55 | P5: 0.58 | Q5: 0.55 | R5: 0.47 | S5: 0.52 | T5: 0.57 | U5: 0.53 | V5: 0.47 | W5: 0.51 | X5: 0.58 | Y5: 0.52 | Z5: 0.48 | AA5: 0.54 | AB5: 0.54 | AC5: 0.53 | AD5: 0.54 | AE5: 0.5 | AF5: 0.5 | AG5: 0.56 | AH5: 0.57 | AI5: 0.56 | AJ5: 0.54 | AK5: 0.53 | AL5: =IFERROR(AVERAGE(E5:AK5),0) -> 0.52575758
A6: Mathematics | B6: C-1.1 | C6: Represents numbers using the place value structure of the Indian number system, compares whole numbers, and knows and can read the names of very large numbers | D6: 0.54 | E6: 0.55 | F6: 0.43 | G6: 0.54 | H6: 0.5 | I6: 0.53 | J6: 0.48 | K6: 0.53 | L6: 0.49 | M6: 0.42 | N6: 0.5 | O6: 0.49 | P6: 0.56 | Q6: 0.55 | R6: 0.51 | S6: 0.51 | T6: 0.59 | U6: 0.51 | V6: 0.44 | W6: 0.49 | X6: 0.56 | Y6: 0.59 | Z6: 0.49 | AA6: 0.55 | AB6: 0.53 | AC6: 0.52 | AD6: 0.53 | AE6: 0.51 | AF6: 0.49 | AG6: 0.56 | AH6: 0.59 | AI6: 0.56 | AJ6: 0.55 | AK6: 0.54 | AL6: =IFERROR(AVERAGE(E6:AK6),0) -> 0.52090909
B7: C-1.2 | C7: Represents and compares commonly used fractions in daily life (such as ½, ¼) as parts of unit wholes, as locations on number lines and as divisions of whole numbers | D7: 0.29 | E7: 0.25 | F7: 0.2 | G7: 0.27 | H7: 0.25 | I7: 0.25 | J7: 0.21 | K7: 0.23 | L7: 0.22 | M7: 0.22 | N7: 0.28 | O7: 0.2 | P7: 0.27 | Q7: 0.27 | R7: 0.24 | S7: 0.23 | T7: 0.25 | U7: 0.24 | V7: 0.19 | W7: 0.27 | X7: 0.27 | Y7: 0.22 | Z7: 0.25 | AA7: 0.22 | AB7: 0.27 | AC7: 0.3 | AD7: 0.2 | AE7: 0.25 | AF7: 0.27 | AG7: 0.25 | AH7: 0.27 | AI7: 0.24 | AJ7: 0.27 | AK7: 0.22 | AL7: =IFERROR(AVERAGE(E7:AK7),0) -> 0.24363636
B8: C-1.3 | C8: Understands and visualises arithmetic operations and the relationships among them, knows addition and multiplication tables at least up to 10×10 (Pahade) and applies the four basic operations on whole numbers to solve daily life problems | D8: 0.53 | E8: 0.46 | F8: 0.41 | G8: 0.46 | H8: 0.43 | I8: 0.48 | J8: 0.42 | K8: 0.45 | L8: 0.45 | M8: 0.38 | N8: 0.48 | O8: 0.44 | P8: 0.49 | Q8: 0.48 | R8: 0.45 | S8: 0.46 | T8: 0.5 | U8: 0.45 | V8: 0.39 | W8: 0.46 | X8: 0.49 | Y8: 0.48 | Z8: 0.41 | AA8: 0.45 | AB8: 0.47 | AC8: 0.46 | AD8: 0.44 | AE8: 0.45 | AF8: 0.45 | AG8: 0.49 | AH8: 0.51 | AI8: 0.47 | AJ8: 0.48 | AK8: 0.46 | AL8: =IFERROR(AVERAGE(E8:AK8),0) -> 0.45606061
B9: C-1.4 | C9: Recognises, describes, and extends simple number patterns such as odd numbers, even numbers, square numbers, cubes, powers of 2, powers of 10, and Virahanka–Fibonacci numbers. | D9: 0.49 | E9: 0.42 | F9: 0.37 | G9: 0.43 | H9: 0.37 | I9: 0.42 | J9: 0.41 | K9: 0.43 | L9: 0.4 | M9: 0.38 | N9: 0.44 | O9: 0.41 | P9: 0.45 | Q9: 0.48 | R9: 0.41 | S9: 0.41 | T9: 0.47 | U9: 0.44 | V9: 0.36 | W9: 0.39 | X9: 0.46 | Y9: 0.41 | Z9: 0.4 | AA9: 0.39 | AB9: 0.47 | AC9: 0.41 | AD9: 0.43 | AE9: 0.44 | AF9: 0.41 | AG9: 0.47 | AH9: 0.46 | AI9: 0.43 | AJ9: 0.44 | AK9: 0.46 | AL9: =IFERROR(AVERAGE(E9:AK9),0) -> 0.42333333
B10: C-2.2 | C10: Describes location and movement using both common language and mathematical vocabulary; understands the notion of map (Najri Naksha) | D10: 0.41 | E10: 0.36 | F10: 0.31 | G10: 0.37 | H10: 0.34 | I10: 0.36 | J10: 0.34 | K10: 0.33 | L10: 0.37 | M10: 0.27 | N10: 0.35 | O10: 0.34 | P10: 0.4 | Q10: 0.37 | R10: 0.34 | S10: 0.35 | T10: 0.4 | U10: 0.37 | V10: 0.31 | W10: 0.34 | X10: 0.38 | Y10: 0.36 | Z10: 0.35 | AA10: 0.35 | AB10: 0.37 | AC10: 0.32 | AD10: 0.33 | AE10: 0.35 | AF10: 0.35 | AG10: 0.39 | AH10: 0.38 | AI10: 0.4 | AJ10: 0.38 | AK10: 0.33 | AL10: =IFERROR(AVERAGE(E10:AK10),0) -> 0.35333333
B11: C-2.4 | C11: Discovers, recognises, describes, and extends patterns in 2D and 3D shapes | D11: 0.48 | E11: 0.44 | F11: 0.39 | G11: 0.47 | H11: 0.41 | I11: 0.47 | J11: 0.39 | K11: 0.46 | L11: 0.42 | M11: 0.38 | N11: 0.45 | O11: 0.44 | P11: 0.47 | Q11: 0.48 | R11: 0.41 | S11: 0.45 | T11: 0.49 | U11: 0.44 | V11: 0.39 | W11: 0.43 | X11: 0.47 | Y11: 0.47 | Z11: 0.41 | AA11: 0.44 | AB11: 0.45 | AC11: 0.42 | AD11: 0.44 | AE11: 0.45 | AF11: 0.43 | AG11: 0.49 | AH11: 0.48 | AI11: 0.5 | AJ11: 0.47 | AK11: 0.45 | AL11: =IFERROR(AVERAGE(E11:AK11),0) -> 0.44393939
